Workbook

Sheet Executive Summary
A1: Workforce Attendance & Overtime Operations Analysis | B1: Workforce Attendance & Overtime Operations Analysis | C1: Workforce Attendance & Overtime Operations Analysis | D1: Workforce Attendance & Overtime Operations Analysis | E1: Workforce Attendance & Overtime Operations Analysis | F1: Workforce Attendance & Overtime Operations Analysis | G1: Workforce Attendance & Overtime Operations Analysis | H1: Workforce Attendance & Overtime Operations Analysis | I1: Workforce Attendance & Overtime Operations Analysis | J1: Workforce Attendance & Overtime Operations Analysis | K1: Workforce Attendance & Overtime Operations Analysis | L1: Workforce Attendance & Overtime Operations Analysis | M1: Workforce Attendance & Overtime Operations Analysis
A2: Workforce Attendance & Overtime Operations Analysis | B2: Workforce Attendance & Overtime Operations Analysis | C2: Workforce Attendance & Overtime Operations Analysis | D2: Workforce Attendance & Overtime Operations Analysis | E2: Workforce Attendance & Overtime Operations Analysis | F2: Workforce Attendance & Overtime Operations Analysis | G2: Workforce Attendance & Overtime Operations Analysis | H2: Workforce Attendance & Overtime Operations Analysis | I2: Workforce Attendance & Overtime Operations Analysis | J2: Workforce Attendance & Overtime Operations Analysis | K2: Workforce Attendance & Overtime Operations Analysis | L2: Workforce Attendance & Overtime Operations Analysis | M2: Workforce Attendance & Overtime Operations Analysis
A4: Synthetic workforce operations sample focused on attendance reliability, late arrivals, absence risk, overtime concentration, coverage gaps, and data quality readiness.
A6: Core KPI | B6: Value | C6: Business Signal | D6: Formula Logic | F6: Leadership Findings
A7: scheduled_shifts | B7: =COUNTA(Raw_Data!$A$2:$A$7080) -> 7079 | C7: Scheduled shift volume. | D7: COUNT(records) | F7: Primary attendance risk | G7: Fulfillment has the highest absence rate at 4.8%.
A8: present_shifts | B8: =SUM(Raw_Data!$AJ$2:$AJ$7080) -> 6838 | C8: Worked shift volume. | D8: SUM(present_flag) | F8: Shift pattern | G8: Overnight shift shows the highest late arrival rate at 10.5%.
A9: attendance_rate | B9: =IFERROR(B8/B7,0) -> 0.96595564 | C9: Core reliability KPI. | D9: present / scheduled | F9: Overtime concentration | G9: Fulfillment and Customer Support represent 55.0% of overtime cost.
A10: absence_count | B10: =SUM(Raw_Data!$AI$2:$AI$7080) -> 241 | C10: Missed shifts. | D10: SUM(absence_flag) | F10: Data readiness | G10: Modeled data quality issue rate is 2.1%, mostly missing clock events and status exceptions.
A11: absence_rate | B11: =IFERROR(B10/B7,0) -> 0.034044357 | C11: Attendance risk KPI. | D11: absence / scheduled | F11: Leadership focus | G11: Repeat lateness, weekend replacement need, and holiday overtime are the strongest action areas.
A12: late_arrival_count | B12: =SUM(Raw_Data!$AH$2:$AH$7080) -> 598 | C12: Late shift count. | D12: SUM(late_flag)
A13: late_arrival_rate | B13: =IFERROR(B12/B7,0) -> 0.084475208 | C13: Arrival reliability KPI. | D13: late / scheduled
A14: average_minutes_late | B14: =IFERROR(AVERAGEIFS(Raw_Data!$AB$2:$AB$7080,Raw_Data!$AH$2:$AH$7080,1),0) -> 20.879599 | C14: Late arrival severity. | D14: AVG(minutes_late)
A15: overtime_hours | B15: =SUM(Raw_Data!$AL$2:$AL$7080) -> 1414.5 | C15: Overtime volume. | D15: SUM(overtime_hours)
A16: overtime_cost | B16: =SUM(Raw_Data!$AP$2:$AP$7080) -> 55844.77 | C16: Estimated overtime cost. | D16: SUM(overtime_labor_cost)
A17: schedule_adherence | B17: =IFERROR(SUM(Raw_Data!$AA$2:$AA$7080)/SUM(Raw_Data!$V$2:$V$7080),0) -> 0.9742174 | C17: Coverage completion. | D17: actual / scheduled
A18: repeat_late_employees | B18: =COUNTIF('Employee Risk'!$F$6:$F$125,">=3") -> 97 | C18: Coaching population. | D18: employees with 3+ lates
A19: coverage_gap_count | B19: =SUM(Raw_Data!$AT$2:$AT$7080) -> 98 | C19: Coverage risk count. | D19: SUM(coverage_gap_flag)
A20: data_quality_issue_rate | B20: =IFERROR(SUM(Raw_Data!$AX$2:$AX$7080)/B7,0) -> 0.020906908 | C20: Reporting trust KPI. | D20: dq issues / records
A23: Week | B23: Attendance Rate | C23: Absence Rate | D23: Late Arrival Rate
A24: 2025-09-29 | B24: 0.9664 | C24: 0.0336 | D24: 0.0646
A25: 2025-10-06 | B25: 0.9512 | C25: 0.0488 | D25: 0.0958
A26: 2025-10-13 | B26: 0.9655 | C26: 0.0345 | D26: 0.1016
A27: 2025-10-20 | B27: 0.9765 | C27: 0.0235 | D27: 0.1013
A28: 2025-10-27 | B28: 0.9617 | C28: 0.0383 | D28: 0.082
A29: 2025-11-03 | B29: 0.9638 | C29: 0.0362 | D29: 0.0797
A30: 2025-11-10 | B30: 0.9616 | C30: 0.0384 | D30: 0.0859
A31: 2025-11-17 | B31: 0.9582 | C31: 0.0418 | D31: 0.0527
A32: 2025-11-24 | B32: 0.949 | C32: 0.051 | D32: 0.0856
A33: 2025-12-01 | B33: 0.9729 | C33: 0.0271 | D33: 0.0812
A34: 2025-12-08 | B34: 0.9782 | C34: 0.0218 | D34: 0.0799
A35: 2025-12-15 | B35: 0.9835 | C35: 0.0165 | D35: 0.0914
... A37: 2025-12-29 | B37: 0.9882 | C37: 0.0118 | D37: 0.1294

Sheet Department Analysis
A1: Department Analysis | B1: Department Analysis | C1: Department Analysis | D1: Department Analysis | E1: Department Analysis | F1: Department Analysis | G1: Department Analysis | H1: Department Analysis | I1: Department Analysis | J1: Department Analysis
A2: Department Analysis | B2: Department Analysis | C2: Department Analysis | D2: Department Analysis | E2: Department Analysis | F2: Department Analysis | G2: Department Analysis | H2: Department Analysis | I2: Department Analysis | J2: Department Analysis
A4: Department | B4: Scheduled Shifts | C4: Attendance Rate | D4: Absence Rate | E4: Late Arrival Rate | F4: Avg Minutes Late | G4: Overtime Hours | H4: Overtime Cost | I4: Coverage Gaps | J4: DQ Issue Rate
A5: Fulfillment | B5: =COUNTIF(Raw_Data!$D$2:$D$7080,A5) -> 1860 | C5: =IFERROR(SUMIFS(Raw_Data!$AJ$2:$AJ$7080,Raw_Data!$D$2:$D$7080,A5)/B5,0) -> 0.95215054 | D5: =IFERROR(SUMIFS(Raw_Data!$AI$2:$AI$7080,Raw_Data!$D$2:$D$7080,A5)/B5,0) -> 0.047849462 | E5: =IFERROR(SUMIFS(Raw_Data!$AH$2:$AH$7080,Raw_Data!$D$2:$D$7080,A5)/B5,0) -> 0.094623656 | F5: =IFERROR(AVERAGEIFS(Raw_Data!$AB$2:$AB$7080,Raw_Data!$D$2:$D$7080,A5,Raw_Data!$AH$2:$AH$7080,1),0) -> 20.278409 | G5: =SUMIFS(Raw_Data!$AL$2:$AL$7080,Raw_Data!$D$2:$D$7080,A5) -> 456 | H5: =SUMIFS(Raw_Data!$AP$2:$AP$7080,Raw_Data!$D$2:$D$7080,A5) -> 17947.91 | I5: =SUMIFS(Raw_Data!$AT$2:$AT$7080,Raw_Data!$D$2:$D$7080,A5) -> 41 | J5: =IFERROR(SUMIFS(Raw_Data!$AX$2:$AX$7080,Raw_Data!$D$2:$D$7080,A5)/B5,0) -> 0.019892473
A6: Customer Support | B6: =COUNTIF(Raw_Data!$D$2:$D$7080,A6) -> 1448 | C6: =IFERROR(SUMIFS(Raw_Data!$AJ$2:$AJ$7080,Raw_Data!$D$2:$D$7080,A6)/B6,0) -> 0.96754144 | D6: =IFERROR(SUMIFS(Raw_Data!$AI$2:$AI$7080,Raw_Data!$D$2:$D$7080,A6)/B6,0) -> 0.032458564 | E6: =IFERROR(SUMIFS(Raw_Data!$AH$2:$AH$7080,Raw_Data!$D$2:$D$7080,A6)/B6,0) -> 0.075966851 | F6: =IFERROR(AVERAGEIFS(Raw_Data!$AB$2:$AB$7080,Raw_Data!$D$2:$D$7080,A6,Raw_Data!$AH$2:$AH$7080,1),0) -> 20 | G6: =SUMIFS(Raw_Data!$AL$2:$AL$7080,Raw_Data!$D$2:$D$7080,A6) -> 312 | H6: =SUMIFS(Raw_Data!$AP$2:$AP$7080,Raw_Data!$D$2:$D$7080,A6) -> 12787.75 | I6: =SUMIFS(Raw_Data!$AT$2:$AT$7080,Raw_Data!$D$2:$D$7080,A6) -> 19 | J6: =IFERROR(SUMIFS(Raw_Data!$AX$2:$AX$7080,Raw_Data!$D$2:$D$7080,A6)/B6,0) -> 0.015883978
A7: Production | B7: =COUNTIF(Raw_Data!$D$2:$D$7080,A7) -> 1619 | C7: =IFERROR(SUMIFS(Raw_Data!$AJ$2:$AJ$7080,Raw_Data!$D$2:$D$7080,A7)/B7,0) -> 0.97282273 | D7: =IFERROR(SUMIFS(Raw_Data!$AI$2:$AI$7080,Raw_Data!$D$2:$D$7080,A7)/B7,0) -> 0.02717727 | E7: =IFERROR(SUMIFS(Raw_Data!$AH$2:$AH$7080,Raw_Data!$D$2:$D$7080,A7)/B7,0) -> 0.090179123 | F7: =IFERROR(AVERAGEIFS(Raw_Data!$AB$2:$AB$7080,Raw_Data!$D$2:$D$7080,A7,Raw_Data!$AH$2:$AH$7080,1),0) -> 21.534247 | G7: =SUMIFS(Raw_Data!$AL$2:$AL$7080,Raw_Data!$D$2:$D$7080,A7) -> 284.5 | H7: =SUMIFS(Raw_Data!$AP$2:$AP$7080,Raw_Data!$D$2:$D$7080,A7) -> 10716.9 | I7: =SUMIFS(Raw_Data!$AT$2:$AT$7080,Raw_Data!$D$2:$D$7080,A7) -> 19 | J7: =IFERROR(SUMIFS(Raw_Data!$AX$2:$AX$7080,Raw_Data!$D$2:$D$7080,A7)/B7,0) -> 0.021000618
A8: Quality Assurance | B8: =COUNTIF(Raw_Data!$D$2:$D$7080,A8) -> 612 | C8: =IFERROR(SUMIFS(Raw_Data!$AJ$2:$AJ$7080,Raw_Data!$D$2:$D$7080,A8)/B8,0) -> 0.97058824 | D8: =IFERROR(SUMIFS(Raw_Data!$AI$2:$AI$7080,Raw_Data!$D$2:$D$7080,A8)/B8,0) -> 0.029411765 | E8: =IFERROR(SUMIFS(Raw_Data!$AH$2:$AH$7080,Raw_Data!$D$2:$D$7080,A8)/B8,0) -> 0.060457516 | F8: =IFERROR(AVERAGEIFS(Raw_Data!$AB$2:$AB$7080,Raw_Data!$D$2:$D$7080,A8,Raw_Data!$AH$2:$AH$7080,1),0) -> 20.918919 | G8: =SUMIFS(Raw_Data!$AL$2:$AL$7080,Raw_Data!$D$2:$D$7080,A8) -> 125.5 | H8: =SUMIFS(Raw_Data!$AP$2:$AP$7080,Raw_Data!$D$2:$D$7080,A8) -> 5142.43 | I8: =SUMIFS(Raw_Data!$AT$2:$AT$7080,Raw_Data!$D$2:$D$7080,A8) -> 5 | J8: =IFERROR(SUMIFS(Raw_Data!$AX$2:$AX$7080,Raw_Data!$D$2:$D$7080,A8)/B8,0) -> 0.031045752
A9: Maintenance | B9: =COUNTIF(Raw_Data!$D$2:$D$7080,A9) -> 813 | C9: =IFERROR(SUMIFS(Raw_Data!$AJ$2:$AJ$7080,Raw_Data!$D$2:$D$7080,A9)/B9,0) -> 0.96555966 | D9: =IFERROR(SUMIFS(Raw_Data!$AI$2:$AI$7080,Raw_Data!$D$2:$D$7080,A9)/B9,0) -> 0.034440344 | E9: =IFERROR(SUMIFS(Raw_Data!$AH$2:$AH$7080,Raw_Data!$D$2:$D$7080,A9)/B9,0) -> 0.10086101 | F9: =IFERROR(AVERAGEIFS(Raw_Data!$AB$2:$AB$7080,Raw_Data!$D$2:$D$7080,A9,Raw_Data!$AH$2:$AH$7080,1),0) -> 19.45122 | G9: =SUMIFS(Raw_Data!$AL$2:$AL$7080,Raw_Data!$D$2:$D$7080,A9) -> 127 | H9: =SUMIFS(Raw_Data!$AP$2:$AP$7080,Raw_Data!$D$2:$D$7080,A9) -> 5276.27 | I9: =SUMIFS(Raw_Data!$AT$2:$AT$7080,Raw_Data!$D$2:$D$7080,A9) -> 9 | J9: =IFERROR(SUMIFS(Raw_Data!$AX$2:$AX$7080,Raw_Data!$D$2:$D$7080,A9)/B9,0) -> 0.035670357
A10: Administration | B10: =COUNTIF(Raw_Data!$D$2:$D$7080,A10) -> 727 | C10: =IFERROR(SUMIFS(Raw_Data!$AJ$2:$AJ$7080,Raw_Data!$D$2:$D$7080,A10)/B10,0) -> 0.97936726 | D10: =IFERROR(SUMIFS(Raw_Data!$AI$2:$AI$7080,Raw_Data!$D$2:$D$7080,A10)/B10,0) -> 0.020632737 | E10: =IFERROR(SUMIFS(Raw_Data!$AH$2:$AH$7080,Raw_Data!$D$2:$D$7080,A10)/B10,0) -> 0.064649243 | F10: =IFERROR(AVERAGEIFS(Raw_Data!$AB$2:$AB$7080,Raw_Data!$D$2:$D$7080,A10,Raw_Data!$AH$2:$AH$7080,1),0) -> 25.617021 | G10: =SUMIFS(Raw_Data!$AL$2:$AL$7080,Raw_Data!$D$2:$D$7080,A10) -> 109.5 | H10: =SUMIFS(Raw_Data!$AP$2:$AP$7080,Raw_Data!$D$2:$D$7080,A10) -> 3973.51 | I10: =SUMIFS(Raw_Data!$AT$2:$AT$7080,Raw_Data!$D$2:$D$7080,A10) -> 5 | J10: =IFERROR(SUMIFS(Raw_Data!$AX$2:$AX$7080,Raw_Data!$D$2:$D$7080,A10)/B10,0) -> 0.0082530949

Sheet Weekly Trend
A1: Weekly Trend Analysis | B1: Weekly Trend Analysis | C1: Weekly Trend Analysis | D1: Weekly Trend Analysis | E1: Weekly Trend Analysis | F1: Weekly Trend Analysis | G1: Weekly Trend Analysis | H1: Weekly Trend Analysis
A2: Weekly Trend Analysis | B2: Weekly Trend Analysis | C2: Weekly Trend Analysis | D2: Weekly Trend Analysis | E2: Weekly Trend Analysis | F2: Weekly Trend Analysis | G2: Weekly Trend Analysis | H2: Weekly Trend Analysis
A4: Week Start | B4: Scheduled Shifts | C4: Attendance Rate | D4: Absence Rate | E4: Late Arrival Rate | F4: Overtime Hours | G4: Overtime Cost | H4: Coverage Gaps
A5: 2025-09-29 | B5: 387 | C5: 0.9664 | D5: 0.0336 | E5: 0.0646 | F5: 65.5 | G5: 2610.4 | H5: 8
A6: 2025-10-06 | B6: 553 | C6: 0.9512 | D6: 0.0488 | E6: 0.0958 | F6: 118 | G6: 4686.42 | H6: 9
A7: 2025-10-13 | B7: 551 | C7: 0.9655 | D7: 0.0345 | E7: 0.1016 | F7: 150.5 | G7: 5940.41 | H7: 7
A8: 2025-10-20 | B8: 553 | C8: 0.9765 | D8: 0.0235 | E8: 0.1013 | F8: 109 | G8: 4479.41 | H8: 7
A9: 2025-10-27 | B9: 549 | C9: 0.9617 | D9: 0.0383 | E9: 0.082 | F9: 77 | G9: 3084.08 | H9: 8
A10: 2025-11-03 | B10: 552 | C10: 0.9638 | D10: 0.0362 | E10: 0.0797 | F10: 85.5 | G10: 3348.83 | H10: 8
A11: 2025-11-10 | B11: 547 | C11: 0.9616 | D11: 0.0384 | E11: 0.0859 | F11: 75.5 | G11: 3102.64 | H11: 9
A12: 2025-11-17 | B12: 550 | C12: 0.9582 | D12: 0.0418 | E12: 0.0527 | F12: 46 | G12: 1812.93 | H12: 6
A13: 2025-11-24 | B13: 549 | C13: 0.949 | D13: 0.051 | E13: 0.0856 | F13: 181 | G13: 6904.32 | H13: 12
A14: 2025-12-01 | B14: 554 | C14: 0.9729 | D14: 0.0271 | E14: 0.0812 | F14: 112 | G14: 4379.77 | H14: 7
A15: 2025-12-08 | B15: 551 | C15: 0.9782 | D15: 0.0218 | E15: 0.0799 | F15: 57.5 | G15: 2276.42 | H15: 6
A16: 2025-12-15 | B16: 547 | C16: 0.9835 | D16: 0.0165 | E16: 0.0914 | F16: 103.5 | G16: 4176.68 | H16: 3
... A18: 2025-12-29 | B18: 85 | C18: 0.9882 | D18: 0.0118 | E18: 0.1294 | F18: 20.5 | G18: 833 | H18: 0

Sheet Employee Risk
A1: Employee Risk Detail | B1: Employee Risk Detail | C1: Employee Risk Detail | D1: Employee Risk Detail | E1: Employee Risk Detail | F1: Employee Risk Detail | G1: Employee Risk Detail | H1: Employee Risk Detail | I1: Employee Risk Detail | J1: Employee Risk Detail | K1: Employee Risk Detail
A2: Employee Risk Detail | B2: Employee Risk Detail | C2: Employee Risk Detail | D2: Employee Risk Detail | E2: Employee Risk Detail | F2: Employee Risk Detail | G2: Employee Risk Detail | H2: Employee Risk Detail | I2: Employee Risk Detail | J2: Employee Risk Detail | K2: Employee Risk Detail
A4: Employee ID | B4: Employee Name | C4: Department | D4: Manager | E4: Scheduled | F4: Late Arrivals | G4: Absences | H4: Overtime Hours | I4: Coverage Gaps | J4: Risk Level | K4: Risk Reason
A5: EMP0090 | B5: Lena Jackson | C5: Fulfillment | D5: Marcus Reed | E5: 64 | F5: 13 | G5: 7 | H5: 21 | I5: 5 | J5: High | K5: Repeat lateness; Recurring absences; High overtime concentration; Coverage gap pattern
A6: EMP0004 | B6: Riley Franklin | C6: Maintenance | D6: Miles Bennett | E6: 66 | F6: 15 | G6: 5 | H6: 7.5 | I6: 2 | J6: High | K6: Repeat lateness; Recurring absences; Coverage gap pattern; Repeated data quality exceptions
A7: EMP0062 | B7: Jasmine Xu | C7: Production | D7: Luis Romero | E7: 66 | F7: 19 | G7: 1 | H7: 10 | I7: 1 | J7: High | K7: Repeat lateness; Repeated data quality exceptions
A8: EMP0054 | B8: Farah Chen | C8: Fulfillment | D8: Marcus Reed | E8: 64 | F8: 14 | G8: 3 | H8: 8.5 | I8: 1 | J8: High | K8: Repeat lateness; Recurring absences; Repeated data quality exceptions
A9: EMP0105 | B9: Drew Foster | C9: Fulfillment | D9: Priya Shah | E9: 64 | F9: 14 | G9: 3 | H9: 26.5 | I9: 1 | J9: High | K9: Repeat lateness; Recurring absences; High overtime concentration
A10: EMP0075 | B10: Trevor Jackson | C10: Maintenance | D10: Miles Bennett | E10: 66 | F10: 10 | G10: 4 | H10: 15.5 | I10: 2 | J10: High | K10: Repeat lateness; Recurring absences; Coverage gap pattern; Repeated data quality exceptions
A11: EMP0031 | B11: Rowan Evans | C11: Fulfillment | D11: Alicia Gomez | E11: 52 | F11: 5 | G11: 5 | H11: 10.5 | I11: 5 | J11: High | K11: Repeat lateness; Recurring absences; Coverage gap pattern
A12: EMP0012 | B12: Kai Keller | C12: Production | D12: Maya Johnson | E12: 52 | F12: 6 | G12: 4 | H12: 7.5 | I12: 5 | J12: High | K12: Repeat lateness; Recurring absences; Coverage gap pattern
A13: EMP0087 | B13: Bianca Diaz | C13: Fulfillment | D13: Priya Shah | E13: 52 | F13: 7 | G13: 4 | H13: 11.5 | I13: 3 | J13: High | K13: Repeat lateness; Recurring absences; Coverage gap pattern
A14: EMP0016 | B14: Jasmine Usman | C14: Production | D14: Maya Johnson | E14: 66 | F14: 7 | G14: 5 | H14: 15.5 | I14: 1 | J14: High | K14: Repeat lateness; Recurring absences
A15: EMP0078 | B15: Rafael Zimmerman | C15: Customer Support | D15: Nina Patel | E15: 65 | F15: 14 | G15: 1 | H15: 18.5 | I15: 0 | J15: High | K15: Repeat lateness; High overtime concentration
A16: EMP0025 | B16: Jamie Nelson | C16: Fulfillment | D16: Priya Shah | E16: 64 | F16: 4 | G16: 6 | H16: 21.5 | I16: 2 | J16: High | K16: Repeat lateness; Recurring absences; High overtime concentration; Coverage gap pattern
... A124: EMP0086 | B124: Jordan Anderson | C124: Administration | D124: Rachel Kim | E124: 65 | F124: 0 | G124: 0 | H124: 9.5 | I124: 0 | J124: Low | K124: No notable repeat attendance risk

Sheet Data Quality
A1: Data Quality Assessment | B1: Data Quality Assessment | C1: Data Quality Assessment | D1: Data Quality Assessment | E1: Data Quality Assessment | F1: Data Quality Assessment | G1: Data Quality Assessment | H1: Data Quality Assessment
A2: Data Quality Assessment | B2: Data Quality Assessment | C2: Data Quality Assessment | D2: Data Quality Assessment | E2: Data Quality Assessment | F2: Data Quality Assessment | G2: Data Quality Assessment | H2: Data Quality Assessment
A4: Issue Type | B4: Records | C4: Issue Rate | D4: Operational Impact | F4: Check | G4: Issue Records | H4: Review Priority
A5: missing_clock_out | B5: 47 | C5: 0.0066 | D5: May understate actual hours or labor cost. | F5: Missing clock-out | G5: 47 | H5: High
A6: missing_clock_in | B6: 31 | C6: 0.0044 | D6: May understate actual hours or labor cost. | F6: Missing clock-in | G6: 31 | H6: High
A7: missing_absence_type | B7: 27 | C7: 0.0038 | D7: May reduce confidence in attendance classification. | F7: Missing absence type | G7: 27 | H7: Medium
A8: status_clock_mismatch | B8: 27 | C8: 0.0038 | D8: May understate actual hours or labor cost. | F8: Status/clock mismatch | G8: 27 | H8: Medium
A9: duplicate_badge_punch | B9: 16 | C9: 0.0023 | D9: May reduce confidence in attendance classification. | F9: Duplicate badge punch | G9: 16 | H9: Medium

Sheet Raw_Data
A1: attendance_record_id | B1: employee_id | C1: employee_name | D1: department | E1: team | F1: manager_id | G1: manager_name | H1: location | I1: job_role | J1: employment_type | K1: hire_date | L1: tenure_band | M1: work_date | N1: week_start_date | O1: month_start_date | P1: day_of_week | Q1: is_weekend | R1: is_holiday | S1: shift_name | T1: scheduled_start_time | U1: scheduled_end_time | V1: scheduled_hours | W1: schedule_type | X1: attendance_status | Y1: actual_clock_in | Z1: actual_clock_out | AA1: actual_hours_worked | AB1: minutes_late | AC1: minutes_left_early | AD1: absence_type | AE1: excused_flag | AF1: no_call_no_show_flag | AG1: partial_shift_flag | AH1: late_flag | AI1: absence_flag | AJ1: present_flag | AK1: regular_hours | AL1: overtime_hours | AM1: hourly_rate | AN1: overtime_rate_multiplier | AO1: regular_labor_cost | AP1: overtime_labor_cost | AQ1: total_labor_cost | AR1: overtime_flag | AS1: high_overtime_flag | AT1: coverage_gap_flag | AU1: replacement_needed_flag | AV1: replacement_employee_id | AW1: attendance_policy_exception_flag | AX1: data_quality_issue_flag | AY1: data_quality_issue_type | AZ1: manager_follow_up_required_flag | BA1: coaching_recommended_flag | BB1: risk_level | BC1: risk_reason | BD1: late_severity_band | BE1: absence_category | BF1: overtime_band | BG1: manager_action_category
A2: AR000001 | B2: EMP0001 | C2: Parker Morris | D2: Administration | E2: Finance Operations | F2: MGR015 | G2: Thomas Nguyen | H2: South Plant | I2: Administrative Specialist | J2: Part-Time | K2: 2020-05-10 | L2: 3+ years | M2: 2025-10-01 | N2: 2025-09-29 | O2: 2025-10-01 | P2: Wednesday | Q2: 0 | R2: 0 | S2: Morning | T2: 06:00 | U2: 14:00 | V2: 8 | W2: Part-Time | X2: Present | Y2: 2025-10-01 06:00 | Z2: 2025-10-01 14:00 | AA2: 8 | AB2: 0 | AC2: 0 | AE2: 0 | AF2: 0 | AG2: 0 | AH2: 0 | AI2: 0 | AJ2: 1 | AK2: 8 | AL2: 0 | AM2: 21.6 | AN2: 1.5 | AO2: 172.8 | AP2: 0 | AQ2: 172.8 | AR2: 0 | AS2: 0 | AT2: 0 | AU2: 0 | AW2: 0 | AX2: 0 | AZ2: 1 | BA2: 1 | BB2: Medium | BC2: Repeat lateness | BD2: On Time | BE2: Not Absent | BF2: No Overtime | BG2: Monitor
A3: AR000002 | B3: EMP0002 | C3: Oscar Turner | D3: Quality Assurance | E3: Inspection | F3: MGR011 | G3: Ethan Clark | H3: North Plant | I3: QA Technician | J3: Full-Time | K3: 2022-01-23 | L3: 3+ years | M3: 2025-10-01 | N3: 2025-09-29 | O3: 2025-10-01 | P3: Wednesday | Q3: 0 | R3: 0 | S3: Morning | T3: 06:00 | U3: 14:00 | V3: 8 | W3: Fixed | X3: Present | Y3: 2025-10-01 06:00 | Z3: 2025-10-01 14:00 | AA3: 8 | AB3: 0 | AC3: 0 | AE3: 0 | AF3: 0 | AG3: 0 | AH3: 0 | AI3: 0 | AJ3: 1 | AK3: 8 | AL3: 0 | AM3: 29.19 | AN3: 1.5 | AO3: 233.52 | AP3: 0 | AQ3: 233.52 | AR3: 0 | AS3: 0 | AT3: 0 | AU3: 0 | AW3: 0 | AX3: 0 | AZ3: 1 | BA3: 1 | BB3: Medium | BC3: Repeat lateness; Recurring absences; Repeated data quality exceptions | BD3: On Time | BE3: Not Absent | BF3: No Overtime | BG3: Monitor
A4: AR000003 | B4: EMP0003 | C4: Jamie Turner | D4: Administration | E4: Finance Operations | F4: MGR014 | G4: Rachel Kim | H4: South Plant | I4: Operations Coordinator | J4: Full-Time | K4: 2022-09-02 | L4: 3+ years | M4: 2025-10-01 | N4: 2025-09-29 | O4: 2025-10-01 | P4: Wednesday | Q4: 0 | R4: 0 | S4: Afternoon | T4: 14:00 | U4: 22:00 | V4: 8 | W4: Fixed | X4: Present | Y4: 2025-10-01 14:00 | Z4: 2025-10-01 22:00 | AA4: 8 | AB4: 0 | AC4: 0 | AE4: 0 | AF4: 0 | AG4: 0 | AH4: 0 | AI4: 0 | AJ4: 1 | AK4: 8 | AL4: 0 | AM4: 27.81 | AN4: 1.5 | AO4: 222.48 | AP4: 0 | AQ4: 222.48 | AR4: 0 | AS4: 0 | AT4: 0 | AU4: 0 | AW4: 0 | AX4: 0 | AZ4: 1 | BA4: 1 | BB4: Medium | BC4: Repeat lateness | BD4: On Time | BE4: Not Absent | BF4: No Overtime | BG4: Monitor
A5: AR000004 | B5: EMP0004 | C5: Riley Franklin | D5: Maintenance | E5: Equipment Repair | F5: MGR013 | G5: Miles Bennett | H5: South Plant | I5: Maintenance Technician | J5: Full-Time | K5: 2025-09-12 | L5: Under 90 days | M5: 2025-10-01 | N5: 2025-09-29 | O5: 2025-10-01 | P5: Wednesday | Q5: 0 | R5: 0 | S5: Overnight | T5: 22:00 | U5: 06:00 | V5: 8 | W5: Fixed | X5: Present | Y5: 2025-10-01 22:00 | Z5: 2025-10-02 06:00 | AA5: 8 | AB5: 0 | AC5: 0 | AE5: 0 | AF5: 0 | AG5: 0 | AH5: 0 | AI5: 0 | AJ5: 1 | AK5: 8 | AL5: 0 | AM5: 25.06 | AN5: 1.5 | AO5: 200.48 | AP5: 0 | AQ5: 200.48 | AR5: 0 | AS5: 0 | AT5: 0 | AU5: 0 | AW5: 0 | AX5: 0 | AZ5: 1 | BA5: 1 | BB5: High | BC5: Repeat lateness; Recurring absences; Coverage gap pattern; Repeated data quality exceptions | BD5: On Time | BE5: Not Absent | BF5: No Overtime | BG5: Coaching recommended
A6: AR000005 | B6: EMP0005 | C6: Sam Garcia | D6: Administration | E6: Finance Operations | F6: MGR014 | G6: Rachel Kim | H6: South Plant | I6: Operations Coordinator | J6: Full-Time | K6: 2025-07-27 | L6: Under 90 days | M6: 2025-10-01 | N6: 2025-09-29 | O6: 2025-10-01 | P6: Wednesday | Q6: 0 | R6: 0 | S6: Afternoon | T6: 14:00 | U6: 22:00 | V6: 8 | W6: Fixed | X6: Present | Y6: 2025-10-01 14:00 | Z6: 2025-10-01 22:00 | AA6: 8 | AB6: 0 | AC6: 0 | AE6: 0 | AF6: 0 | AG6: 0 | AH6: 0 | AI6: 0 | AJ6: 1 | AK6: 8 | AL6: 0 | AM6: 22.49 | AN6: 1.5 | AO6: 179.92 | AP6: 0 | AQ6: 179.92 | AR6: 0 | AS6: 0 | AT6: 0 | AU6: 0 | AW6: 0 | AX6: 0 | AZ6: 1 | BA6: 1 | BB6: Medium | BC6: Repeat lateness | BD6: On Time | BE6: Not Absent | BF6: No Overtime | BG6: Monitor
A7: AR000006 | B7: EMP0006 | C7: Trevor Morris | D7: Production | E7: Line A | F7: MGR008 | G7: Maya Johnson | H7: North Plant | I7: Production Operator | J7: Full-Time | K7: 2023-07-01 | L7: 1 to 3 years | M7: 2025-10-01 | N7: 2025-09-29 | O7: 2025-10-01 | P7: Wednesday | Q7: 0 | R7: 0 | S7: Morning | T7: 06:00 | U7: 14:00 | V7: 8 | W7: Fixed | X7: Present | Y7: 2025-10-01 06:00 | Z7: 2025-10-01 14:00 | AA7: 8 | AB7: 0 | AC7: 0 | AE7: 0 | AF7: 0 | AG7: 0 | AH7: 0 | AI7: 0 | AJ7: 1 | AK7: 8 | AL7: 0 | AM7: 22.25 | AN7: 1.5 | AO7: 178 | AP7: 0 | AQ7: 178 | AR7: 0 | AS7: 0 | AT7: 0 | AU7: 0 | AW7: 0 | AX7: 0 | AZ7: 0 | BA7: 0 | BB7: Low | BC7: No notable repeat attendance risk | BD7: On Time | BE7: Not Absent | BF7: No Overtime | BG7: No action
A8: AR000007 | B8: EMP0007 | C8: Elena Stewart | D8: Production | E8: Line A | F8: MGR007 | G8: Owen Carter | H8: North Plant | I8: Line Lead | J8: Full-Time | K8: 2024-01-04 | L8: 1 to 3 years | M8: 2025-10-01 | N8: 2025-09-29 | O8: 2025-10-01 | P8: Wednesday | Q8: 0 | R8: 0 | S8: Afternoon | T8: 14:00 | U8: 22:00 | V8: 8 | W8: Fixed | X8: Present | Y8: 2025-10-01 14:00 | Z8: 2025-10-01 22:00 | AA8: 8 | AB8: 0 | AC8: 0 | AE8: 0 | AF8: 0 | AG8: 0 | AH8: 0 | AI8: 0 | AJ8: 1 | AK8: 8 | AL8: 0 | AM8: 27.58 | AN8: 1.5 | AO8: 220.64 | AP8: 0 | AQ8: 220.64 | AR8: 0 | AS8: 0 | AT8: 0 | AU8: 0 | AW8: 0 | AX8: 0 | AZ8: 1 | BA8: 1 | BB8: Medium | BC8: Repeat lateness; Repeated data quality exceptions | BD8: On Time | BE8: Not Absent | BF8: No Overtime | BG8: Monitor
A9: AR000008 | B9: EMP0008 | C9: Jamie Morris | D9: Production | E9: Line A | F9: MGR009 | G9: Luis Romero | H9: South Plant | I9: Line Lead | J9: Full-Time | K9: 2021-07-17 | L9: 3+ years | M9: 2025-10-01 | N9: 2025-09-29 | O9: 2025-10-01 | P9: Wednesday | Q9: 0 | R9: 0 | S9: Evening | T9: 16:00 | U9: 00:00 | V9: 8 | W9: Fixed | X9: Present | Y9: 2025-10-01 16:00 | Z9: 2025-10-02 00:00 | AA9: 8 | AB9: 0 | AC9: 0 | AE9: 0 | AF9: 0 | AG9: 0 | AH9: 0 | AI9: 0 | AJ9: 1 | AK9: 8 | AL9: 0 | AM9: 29.2 | AN9: 1.5 | AO9: 233.6 | AP9: 0 | AQ9: 233.6 | AR9: 0 | AS9: 0 | AT9: 0 | AU9: 0 | AW9: 0 | AX9: 0 | AZ9: 1 | BA9: 1 | BB9: High | BC9: Repeat lateness | BD9: On Time | BE9: Not Absent | BF9: No Overtime | BG9: Coaching recommended
A10: AR000009 | B10: EMP0009 | C10: Sam Morris | D10: Customer Support | E10: Tier 1 Support | F10: MGR004 | G10: Daniel Brooks | H10: South Plant | I10: Support Team Lead | J10: Full-Time | K10: 2023-06-27 | L10: 1 to 3 years | M10: 2025-10-01 | N10: 2025-09-29 | O10: 2025-10-01 | P10: Wednesday | Q10: 0 | R10: 0 | S10: Morning | T10: 06:00 | U10: 14:00 | V10: 8 | W10: Rotating | X10: Present | Y10: 2025-10-01 06:00 | Z10: 2025-10-01 14:00 | AA10: 8 | AB10: 0 | AC10: 0 | AE10: 0 | AF10: 0 | AG10: 0 | AH10: 0 | AI10: 0 | AJ10: 1 | AK10: 8 | AL10: 0 | AM10: 28.16 | AN10: 1.5 | AO10: 225.28 | AP10: 0 | AQ10: 225.28 | AR10: 0 | AS10: 0 | AT10: 0 | AU10: 0 | AW10: 0 | AX10: 0 | AZ10: 1 | BA10: 1 | BB10: High | BC10: Repeat lateness | BD10: On Time | BE10: Not Absent | BF10: No Overtime | BG10: Coaching recommended
A11: AR000010 | B11: EMP0011 | C11: Cameron Garcia | D11: Customer Support | E11: Account Support | F11: MGR004 | G11: Daniel Brooks | H11: North Plant | I11: Support Team Lead | J11: Temporary | K11: 2020-07-16 | L11: 3+ years | M11: 2025-10-01 | N11: 2025-09-29 | O11: 2025-10-01 | P11: Wednesday | Q11: 0 | R11: 0 | S11: Evening | T11: 16:00 | U11: 00:00 | V11: 8 | W11: Rotating | X11: Present | Y11: 2025-10-01 16:00 | Z11: 2025-10-02 00:00 | AA11: 8 | AB11: 0 | AC11: 0 | AE11: 0 | AF11: 0 | AG11: 0 | AH11: 0 | AI11: 0 | AJ11: 1 | AK11: 8 | AL11: 0 | AM11: 30.24 | AN11: 1.5 | AO11: 241.92 | AP11: 0 | AQ11: 241.92 | AR11: 0 | AS11: 0 | AT11: 0 | AU11: 0 | AW11: 0 | AX11: 0 | AZ11: 1 | BA11: 1 | BB11: Medium | BC11: Repeat lateness; High overtime concentration | BD11: On Time | BE11: Not Absent | BF11: No Overtime | BG11: Schedule review
A12: AR000011 | B12: EMP0013 | C12: Farah Quinn | D12: Fulfillment | E12: Picking | F12: MGR003 | G12: Priya Shah | H12: Distribution Center | I12: Inventory Coordinator | J12: Full-Time | K12: 2021-05-06 | L12: 3+ years | M12: 2025-10-01 | N12: 2025-09-29 | O12: 2025-10-01 | P12: Wednesday | Q12: 0 | R12: 0 | S12: Evening | T12: 16:00 | U12: 00:00 | V12: 8 | W12: Fixed | X12: Present | Y12: 2025-10-01 16:00 | Z12: 2025-10-02 00:00 | AA12: 8 | AB12: 0 | AC12: 0 | AE12: 0 | AF12: 0 | AG12: 0 | AH12: 0 | AI12: 0 | AJ12: 1 | AK12: 8 | AL12: 0 | AM12: 22.59 | AN12: 1.5 | AO12: 180.72 | AP12: 0 | AQ12: 180.72 | AR12: 0 | AS12: 0 | AT12: 0 | AU12: 0 | AW12: 0 | AX12: 0 | AZ12: 1 | BA12: 1 | BB12: Medium | BC12: Repeat lateness | BD12: On Time | BE12: Not Absent | BF12: No Overtime | BG12: Monitor
A13: AR000012 | B13: EMP0015 | C13: Drew Hughes | D13: Fulfillment | E13: Packing | F13: MGR001 | G13: Alicia Gomez | H13: North Plant | I13: Inventory Coordinator | J13: Full-Time | K13: 2025-09-07 | L13: Under 90 days | M13: 2025-10-01 | N13: 2025-09-29 | O13: 2025-10-01 | P13: Wednesday | Q13: 0 | R13: 0 | S13: Evening | T13: 16:00 | U13: 00:00 | V13: 8 | W13: Fixed | X13: Present | Y13: 2025-10-01 16:00 | Z13: 2025-10-02 00:00 | AA13: 8 | AB13: 0 | AC13: 0 | AE13: 0 | AF13: 0 | AG13: 0 | AH13: 0 | AI13: 0 | AJ13: 1 | AK13: 8 | AL13: 0 | AM13: 22.77 | AN13: 1.5 | AO13: 182.16 | AP13: 0 | AQ13: 182.16 | AR13: 0 | AS13: 0 | AT13: 0 | AU13: 0 | AW13: 0 | AX13: 0 | AZ13: 1 | BA13: 1 | BB13: High | BC13: Repeat lateness; Recurring absences | BD13: On Time | BE13: Not Absent | BF13: No Overtime | BG13: Coaching recommended
... A17: AR000016 | B17: EMP0019 | C17: Rafael Ortiz | D17: Customer Support | E17: Account Support | F17: MGR005 | G17: Nina Patel | H17: South Plant | I17: Support Specialist | J17: Full-Time | K17: 2025-08-01 | L17: Under 90 days | M17: 2025-10-01 | N17: 2025-09-29 | O17: 2025-10-01 | P17: Wednesday | Q17: 0 | R17: 0 | S17: Evening | T17: 16:00 | U17: 00:00 | V17: 8 | W17: Fixed | X17: Present | Y17: 2025-10-01 16:00 | Z17: 2025-10-02 00:00 | AA17: 8 | AB17: 0 | AC17: 0 | AE17: 0 | AF17: 0 | AG17: 0 | AH17: 0 | AI17: 0 | AJ17: 1 | AK17: 8 | AL17: 0 | AM17: 21.58 | AN17: 1.5 | AO17: 172.64 | AP17: 0 | AQ17: 172.64 | AR17: 0 | AS17: 0 | AT17: 0 | AU17: 0 | AW17: 0 | AX17: 0 | AZ17: 0 | BA17: 0 | BB17: Medium | BC17: High overtime concentration; Repeated data quality exceptions | BD17: On Time | BE17: Not Absent | BF17: No Overtime | BG17: Schedule review
A18: AR000017 | B18: EMP0020 | C18: Hannah Roberts | D18: Fulfillment | E18: Picking | F18: MGR001 | G18: Alicia Gomez | H18: Distribution Center | I18: Warehouse Associate | J18: Full-Time | K18: 2022-08-29 | L18: 3+ years | M18: 2025-10-01 | N18: 2025-09-29 | O18: 2025-10-01 | P18: Wednesday | Q18: 0 | R18: 0 | S18: Overnight | T18: 22:00 | U18: 06:00 | V18: 8 | W18: Fixed | X18: No Call No Show | AA18: 0 | AB18: 0 | AC18: 0 | AD18: No Call No Show | AE18: 0 | AF18: 1 | AG18: 0 | AH18: 0 | AI18: 1 | AJ18: 0 | AK18: 0 | AL18: 0 | AM18: 19.78 | AN18: 1.5 | AO18: 0 | AP18: 0 | AQ18: 0 | AR18: 0 | AS18: 0 | AT18: 0 | AU18: 0 | AW18: 0 | AX18: 0 | AZ18: 1 | BA18: 1 | BB18: High | BC18: Repeat lateness; Repeated data quality exceptions | BD18: On Time | BE18: No Call No Show | BF18: No Overtime | BG18: Attendance follow-up
A19: AR000018 | B19: EMP0021 | C19: Jamie Hughes | D19: Maintenance | E19: Equipment Repair | F19: MGR012 | G19: Sofia Rivera | H19: North Plant | I19: Maintenance Technician | J19: Full-Time | K19: 2023-04-14 | L19: 1 to 3 years | M19: 2025-10-01 | N19: 2025-09-29 | O19: 2025-10-01 | P19: Wednesday | Q19: 0 | R19: 0 | S19: Afternoon | T19: 14:00 | U19: 22:00 | V19: 8 | W19: Weekend Support | X19: Present | Y19: 2025-10-01 14:00 | Z19: 2025-10-01 22:00 | AA19: 8 | AB19: 0 | AC19: 0 | AE19: 0 | AF19: 0 | AG19: 0 | AH19: 0 | AI19: 0 | AJ19: 1 | AK19: 8 | AL19: 0 | AM19: 27.83 | AN19: 1.5 | AO19: 222.64 | AP19: 0 | AQ19: 222.64 | AR19: 0 | AS19: 0 | AT19: 0 | AU19: 0 | AW19: 0 | AX19: 0 | AZ19: 1 | BA19: 1 | BB19: High | BC19: Repeat lateness; Repeated data quality exceptions | BD19: On Time | BE19: Not Absent | BF19: No Overtime | BG19: Coaching recommended
A20: AR000019 | B20: EMP0022 | C20: Hannah Anderson | D20: Customer Support | E20: Account Support | F20: MGR004 | G20: Daniel Brooks | H20: Remote Support | I20: Support Team Lead | J20: Part-Time | K20: 2025-07-25 | L20: Under 90 days | M20: 2025-10-01 | N20: 2025-09-29 | O20: 2025-10-01 | P20: Wednesday | Q20: 0 | R20: 0 | S20: Morning | T20: 06:00 | U20: 14:00 | V20: 8 | W20: Rotating | X20: Present | Y20: 2025-10-01 06:00 | Z20: 2025-10-01 14:00 | AA20: 8 | AB20: 0 | AC20: 0 | AE20: 0 | AF20: 0 | AG20: 0 | AH20: 0 | AI20: 0 | AJ20: 1 | AK20: 8 | AL20: 0 | AM20: 28.52 | AN20: 1.5 | AO20: 228.16 | AP20: 0 | AQ20: 228.16 | AR20: 0 | AS20: 0 | AT20: 0 | AU20: 0 | AW20: 0 | AX20: 0 | AZ20: 1 | BA20: 1 | BB20: Medium | BC20: Repeat lateness; Coverage gap pattern | BD20: On Time | BE20: Not Absent | BF20: No Overtime | BG20: Monitor
A21: AR000020 | B21: EMP0023 | C21: Alex Harris | D21: Fulfillment | E21: Inventory Control | F21: MGR001 | G21: Alicia Gomez | H21: South Plant | I21: Inventory Coordinator | J21: Temporary | K21: 2025-07-08 | L21: Under 90 days | M21: 2025-10-01 | N21: 2025-09-29 | O21: 2025-10-01 | P21: Wednesday | Q21: 0 | R21: 0 | S21: Morning | T21: 06:00 | U21: 14:00 | V21: 8 | W21: Rotating | X21: Present | Y21: 2025-10-01 06:00 | Z21: 2025-10-01 15:00 | AA21: 9 | AB21: 0 | AC21: 0 | AE21: 0 | AF21: 0 | AG21: 0 | AH21: 0 | AI21: 0 | AJ21: 1 | AK21: 8 | AL21: 1 | AM21: 25.99 | AN21: 1.5 | AO21: 207.92 | AP21: 38.99 | AQ21: 246.91 | AR21: 1 | AS21: 0 | AT21: 0 | AU21: 0 | AW21: 0 | AX21: 0 | AZ21: 1 | BA21: 1 | BB21: Medium | BC21: Repeat lateness | BD21: On Time | BE21: Not Absent | BF21: 0.5-2.0 hours | BG21: Monitor
A22: AR000021 | B22: EMP0024 | C22: Oscar Young | D22: Fulfillment | E22: Picking | F22: MGR003 | G22: Priya Shah | H22: Distribution Center | I22: Fulfillment Lead | J22: Full-Time | K22: 2020-11-20 | L22: 3+ years | M22: 2025-10-01 | N22: 2025-09-29 | O22: 2025-10-01 | P22: Wednesday | Q22: 0 | R22: 0 | S22: Morning | T22: 06:00 | U22: 14:00 | V22: 8 | W22: Fixed | X22: Present | Y22: 2025-10-01 06:00 | Z22: 2025-10-01 14:00 | AA22: 8 | AB22: 0 | AC22: 0 | AE22: 0 | AF22: 0 | AG22: 0 | AH22: 0 | AI22: 0 | AJ22: 1 | AK22: 8 | AL22: 0 | AM22: 27.18 | AN22: 1.5 | AO22: 217.44 | AP22: 0 | AQ22: 217.44 | AR22: 0 | AS22: 0 | AT22: 0 | AU22: 0 | AW22: 0 | AX22: 0 | AZ22: 1 | BA22: 1 | BB22: Medium | BC22: Repeat lateness | BD22: On Time | BE22: Not Absent | BF22: No Overtime | BG22: Monitor
A23: AR000022 | B23: EMP0025 | C23: Jamie Nelson | D23: Fulfillment | E23: Picking | F23: MGR003 | G23: Priya Shah | H23: Distribution Center | I23: Warehouse Associate | J23: Full-Time | K23: 2023-03-06 | L23: 1 to 3 years | M23: 2025-10-01 | N23: 2025-09-29 | O23: 2025-10-01 | P23: Wednesday | Q23: 0 | R23: 0 | S23: Overnight | T23: 22:00 | U23: 06:00 | V23: 8 | W23: Fixed | X23: Present | Y23: 2025-10-01 22:00 | Z23: 2025-10-02 08:30 | AA23: 10.5 | AB23: 0 | AC23: 0 | AE23: 0 | AF23: 0 | AG23: 0 | AH23: 0 | AI23: 0 | AJ23: 1 | AK23: 8 | AL23: 2.5 | AM23: 18.05 | AN23: 1.5 | AO23: 144.4 | AP23: 67.69 | AQ23: 212.09 | AR23: 1 | AS23: 0 | AT23: 0 | AU23: 0 | AW23: 0 | AX23: 0 | AZ23: 1 | BA23: 1 | BB23: High | BC23: Repeat lateness; Recurring absences; High overtime concentration; Coverage gap pattern | BD23: On Time | BE23: Not Absent | BF23: 2.25-4.0 hours | BG23: Coaching recommended
A24: AR000023 | B24: EMP0026 | C24: Hannah Usman | D24: Quality Assurance | E24: Testing | F24: MGR010 | G24: Grace Allen | H24: Distribution Center | I24: QA Technician | J24: Full-Time | K24: 2023-07-04 | L24: 1 to 3 years | M24: 2025-10-01 | N24: 2025-09-29 | O24: 2025-10-01 | P24: Wednesday | Q24: 0 | R24: 0 | S24: Morning | T24: 06:00 | U24: 14:00 | V24: 8 | W24: Fixed | X24: Present | Y24: 2025-10-01 06:00 | Z24: 2025-10-01 14:00 | AA24: 8 | AB24: 0 | AC24: 0 | AE24: 0 | AF24: 0 | AG24: 0 | AH24: 0 | AI24: 0 | AJ24: 1 | AK24: 8 | AL24: 0 | AM24: 26.85 | AN24: 1.5 | AO24: 214.8 | AP24: 0 | AQ24: 214.8 | AR24: 0 | AS24: 0 | AT24: 0 | AU24: 0 | AW24: 0 | AX24: 0 | AZ24: 0 | BA24: 0 | BB24: Low | BC24: Repeated data quality exceptions | BD24: On Time | BE24: Not Absent | BF24: No Overtime | BG24: No action
A25: AR000024 | B25: EMP0027 | C25: Taylor Jackson | D25: Fulfillment | E25: Inventory Control | F25: MGR003 | G25: Priya Shah | H25: Distribution Center | I25: Inventory Coordinator | J25: Full-Time | K25: 2025-07-12 | L25: Under 90 days | M25: 2025-10-01 | N25: 2025-09-29 | O25: 2025-10-01 | P25: Wednesday | Q25: 0 | R25: 0 | S25: Afternoon | T25: 14:00 | U25: 22:00 | V25: 8 | W25: Rotating | X25: Present | Y25: 2025-10-01 14:00 | Z25: 2025-10-01 22:00 | AA25: 8 | AB25: 0 | AC25: 0 | AE25: 0 | AF25: 0 | AG25: 0 | AH25: 0 | AI25: 0 | AJ25: 1 | AK25: 8 | AL25: 0 | AM25: 21.81 | AN25: 1.5 | AO25: 174.48 | AP25: 0 | AQ25: 174.48 | AR25: 0 | AS25: 0 | AT25: 0 | AU25: 0 | AW25: 0 | AX25: 0 | AZ25: 1 | BA25: 1 | BB25: Medium | BC25: Repeat lateness | BD25: On Time | BE25: Not Absent | BF25: No Overtime | BG25: Monitor
A26: AR000025 | B26: EMP0028 | C26: Riley Baker | D26: Fulfillment | E26: Picking | F26: MGR003 | G26: Priya Shah | H26: Distribution Center | I26: Fulfillment Lead | J26: Full-Time | K26: 2020-11-09 | L26: 3+ years | M26: 2025-10-01 | N26: 2025-09-29 | O26: 2025-10-01 | P26: Wednesday | Q26: 0 | R26: 0 | S26: Afternoon | T26: 14:00 | U26: 22:00 | V26: 8 | W26: Fixed | X26: Present | Y26: 2025-10-01 14:00 | Z26: 2025-10-01 22:00 | AA26: 8 | AB26: 0 | AC26: 0 | AE26: 0 | AF26: 0 | AG26: 0 | AH26: 0 | AI26: 0 | AJ26: 1 | AK26: 8 | AL26: 0 | AM26: 27.77 | AN26: 1.5 | AO26: 222.16 | AP26: 0 | AQ26: 222.16 | AR26: 0 | AS26: 0 | AT26: 0 | AU26: 0 | AW26: 0 | AX26: 0 | AZ26: 1 | BA26: 1 | BB26: Medium | BC26: Repeat lateness; Recurring absences | BD26: On Time | BE26: Not Absent | BF26: No Overtime | BG26: Monitor
A27: AR000026 | B27: EMP0029 | C27: Sam Morris | D27: Fulfillment | E27: Packing | F27: MGR001 | G27: Alicia Gomez | H27: Distribution Center | I27: Fulfillment Lead | J27: Full-Time | K27: 2022-01-13 | L27: 3+ years | M27: 2025-10-01 | N27: 2025-09-29 | O27: 2025-10-01 | P27: Wednesday | Q27: 0 | R27: 0 | S27: Afternoon | T27: 14:00 | U27: 22:00 | V27: 8 | W27: Weekend Support | X27: Present | Y27: 2025-10-01 14:00 | Z27: 2025-10-02 01:00 | AA27: 11 | AB27: 0 | AC27: 0 | AE27: 0 | AF27: 0 | AG27: 0 | AH27: 0 | AI27: 0 | AJ27: 1 | AK27: 8 | AL27: 3 | AM27: 31.9 | AN27: 1.5 | AO27: 255.2 | AP27: 143.55 | AQ27: 398.75 | AR27: 1 | AS27: 0 | AT27: 0 | AU27: 0 | AW27: 0 | AX27: 0 | AZ27: 0 | BA27: 0 | BB27: Medium | BC27: High overtime concentration | BD27: On Time | BE27: Not Absent | BF27: 2.25-4.0 hours | BG27: Schedule review
A28: AR000027 | B28: EMP0030 | C28: Parker Garcia | D28: Administration | E28: Office Services | F28: MGR014 | G28: Rachel Kim | H28: South Plant | I28: Operations Coordinator | J28: Full-Time | K28: 2024-07-22 | L28: 1 to 3 years | M28: 2025-10-01 | N28: 2025-09-29 | O28: 2025-10-01 | P28: Wednesday | Q28: 0 | R28: 0 | S28: Evening | T28: 16:00 | U28: 00:00 | V28: 8 | W28: Fixed | X28: Present | Y28: 2025-10-01 16:00 | Z28: 2025-10-02 00:00 | AA28: 8 | AB28: 0 | AC28: 0 | AE28: 0 | AF28: 0 | AG28: 0 | AH28: 0 | AI28: 0 | AJ28: 1 | AK28: 8 | AL28: 0 | AM28: 22.82 | AN28: 1.5 | AO28: 182.56 | AP28: 0 | AQ28: 182.56 | AR28: 0 | AS28: 0 | AT28: 0 | AU28: 0 | AW28: 0 | AX28: 0 | AZ28: 1 | BA28: 1 | BB28: Medium | BC28: Repeat lateness | BD28: On Time | BE28: Not Absent | BF28: No Overtime | BG28: Monitor
A29: AR000028 | B29: EMP0031 | C29: Rowan Evans | D29: Fulfillment | E29: Picking | F29: MGR001 | G29: Alicia Gomez | H29: Distribution Center | I29: Fulfillment Lead | J29: Part-Time | K29: 2025-07-21 | L29: Under 90 days | M29: 2025-10-01 | N29: 2025-09-29 | O29: 2025-10-01 | P29: Wednesday | Q29: 0 | R29: 0 | S29: Overnight | T29: 22:00 | U29: 06:00 | V29: 8 | W29: Part-Time | X29: Partial Shift | Y29: 2025-10-01 22:00 | Z29: 2025-10-02 04:57 | AA29: 6.95 | AB29: 0 | AC29: 63 | AE29: 0 | AF29: 0 | AG29: 1 | AH29: 0 | AI29: 0 | AJ29: 1 | AK29: 6.95 | AL29: 0 | AM29: 31.68 | AN29: 1.5 | AO29: 220.18 | AP29: 0 | AQ29: 220.18 | AR29: 0 | AS29: 0 | AT29: 1 | AU29: 1 | AV29: EMP0057 | AW29: 0 | AX29: 0 | AZ29: 1 | BA29: 1 | BB29: High | BC29: Repeat lateness; Recurring absences; Coverage gap pattern | BD29: On Time | BE29: Not Absent | BF29: No Overtime | BG29: Coaching recommended
A30: AR000029 | B30: EMP0032 | C30: Diana Walker | D30: Fulfillment | E30: Picking | F30: MGR002 | G30: Marcus Reed | H30: North Plant | I30: Warehouse Associate | J30: Full-Time | K30: 2023-01-06 | L30: 1 to 3 years | M30: 2025-10-01 | N30: 2025-09-29 | O30: 2025-10-01 | P30: Wednesday | Q30: 0 | R30: 0 | S30: Afternoon | T30: 14:00 | U30: 22:00 | V30: 8 | W30: Fixed | X30: Present | Y30: 2025-10-01 14:00 | Z30: 2025-10-01 22:00 | AA30: 8 | AB30: 0 | AC30: 0 | AE30: 0 | AF30: 0 | AG30: 0 | AH30: 0 | AI30: 0 | AJ30: 1 | AK30: 8 | AL30: 0 | AM30: 17.93 | AN30: 1.5 | AO30: 143.44 | AP30: 0 | AQ30: 143.44 | AR30: 0 | AS30: 0 | AT30: 0 | AU30: 0 | AW30: 0 | AX30: 0 | AZ30: 1 | BA30: 1 | BB30: Medium | BC30: Repeat lateness; Recurring absences; High overtime concentration; Coverage gap pattern | BD30: On Time | BE30: Not Absent | BF30: No Overtime | BG30: Schedule review
A31: AR000030 | B31: EMP0035 | C31: Kevin Baker | D31: Maintenance | E31: Equipment Repair | F31: MGR013 | G31: Miles Bennett | H31: South Plant | I31: Facilities Coordinator | J31: Full-Time | K31: 2020-09-01 | L31: 3+ years | M31: 2025-10-01 | N31: 2025-09-29 | O31: 2025-10-01 | P31: Wednesday | Q31: 0 | R31: 0 | S31: Afternoon | T31: 14:00 | U31: 22:00 | V31: 8 | W31: Rotating | X31: Present | Y31: 2025-10-01 14:00 | Z31: 2025-10-01 22:00 | AA31: 8 | AB31: 0 | AC31: 0 | AE31: 0 | AF31: 0 | AG31: 0 | AH31: 0 | AI31: 0 | AJ31: 1 | AK31: 8 | AL31: 0 | AM31: 28.39 | AN31: 1.5 | AO31: 227.12 | AP31: 0 | AQ31: 227.12 | AR31: 0 | AS31: 0 | AT31: 0 | AU31: 0 | AW31: 0 | AX31: 0 | AZ31: 1 | BA31: 1 | BB31: High | BC31: Repeat lateness; Recurring absences; Coverage gap pattern | BD31: On Time | BE31: Not Absent | BF31: No Overtime | BG31: Coaching recommended
A32: AR000031 | B32: EMP0036 | C32: Trevor Garcia | D32: Fulfillment | E32: Inventory Control | F32: MGR003 | G32: Priya Shah | H32: Distribution Center | I32: Inventory Coordinator | J32: Full-Time | K32: 2024-03-08 | L32: 1 to 3 years | M32: 2025-10-01 | N32: 2025-09-29 | O32: 2025-10-01 | P32: Wednesday | Q32: 0 | R32: 0 | S32: Overnight | T32: 22:00 | U32: 06:00 | V32: 8 | W32: Fixed | X32: Present | Y32: 2025-10-01 22:00 | Z32: 2025-10-02 06:00 | AA32: 8 | AB32: 0 | AC32: 0 | AE32: 0 | AF32: 0 | AG32: 0 | AH32: 0 | AI32: 0 | AJ32: 1 | AK32: 8 | AL32: 0 | AM32: 27.78 | AN32: 1.5 | AO32: 222.24 | AP32: 0 | AQ32: 222.24 | AR32: 0 | AS32: 0 | AT32: 0 | AU32: 0 | AW32: 0 | AX32: 0 | AZ32: 1 | BA32: 1 | BB32: Medium | BC32: Repeat lateness | BD32: On Time | BE32: Not Absent | BF32: No Overtime | BG32: Monitor
A33: AR000032 | B33: EMP0038 | C33: Riley Evans | D33: Production | E33: Line B | F33: MGR009 | G33: Luis Romero | H33: South Plant | I33: Production Operator | J33: Full-Time | K33: 2020-07-01 | L33: 3+ years | M33: 2025-10-01 | N33: 2025-09-29 | O33: 2025-10-01 | P33: Wednesday | Q33: 0 | R33: 0 | S33: Evening | T33: 16:00 | U33: 00:00 | V33: 8 | W33: Weekend Support | X33: Present | Y33: 2025-10-01 16:00 | Z33: 2025-10-02 00:00 | AA33: 8 | AB33: 0 | AC33: 0 | AE33: 0 | AF33: 0 | AG33: 0 | AH33: 0 | AI33: 0 | AJ33: 1 | AK33: 8 | AL33: 0 | AM33: 25.38 | AN33: 1.5 | AO33: 203.04 | AP33: 0 | AQ33: 203.04 | AR33: 0 | AS33: 0 | AT33: 0 | AU33: 0 | AW33: 0 | AX33: 0 | AZ33: 1 | BA33: 1 | BB33: Medium | BC33: Repeat lateness | BD33: On Time | BE33: Not Absent | BF33: No Overtime | BG33: Monitor
A34: AR000033 | B34: EMP0039 | C34: Parker Xu | D34: Customer Support | E34: Account Support | F34: MGR006 | G34: Harper Lee | H34: South Plant | I34: Customer Care Analyst | J34: Full-Time | K34: 2020-02-10 | L34: 3+ years | M34: 2025-10-01 | N34: 2025-09-29 | O34: 2025-10-01 | P34: Wednesday | Q34: 0 | R34: 0 | S34: Afternoon | T34: 14:00 | U34: 22:00 | V34: 8 | W34: Rotating | X34: Present | Y34: 2025-10-01 14:00 | Z34: 2025-10-01 22:00 | AA34: 8 | AB34: 0 | AC34: 0 | AE34: 0 | AF34: 0 | AG34: 0 | AH34: 0 | AI34: 0 | AJ34: 1 | AK34: 8 | AL34: 0 | AM34: 27.06 | AN34: 1.5 | AO34: 216.48 | AP34: 0 | AQ34: 216.48 | AR34: 0 | AS34: 0 | AT34: 0 | AU34: 0 | AW34: 0 | AX34: 0 | AZ34: 1 | BA34: 1 | BB34: Medium | BC34: Repeat lateness; Repeated data quality exceptions | BD34: On Time | BE34: Not Absent | BF34: No Overtime | BG34: Monitor
A35: AR000034 | B35: EMP0040 | C35: Parker Franklin | D35: Production | E35: Line A | F35: MGR008 | G35: Maya Johnson | H35: North Plant | I35: Production Operator | J35: Full-Time | K35: 2020-11-12 | L35: 3+ years | M35: 2025-10-01 | N35: 2025-09-29 | O35: 2025-10-01 | P35: Wednesday | Q35: 0 | R35: 0 | S35: Evening | T35: 16:00 | U35: 00:00 | V35: 8 | W35: Fixed | X35: Present | Y35: 2025-10-01 16:00 | Z35: 2025-10-02 00:00 | AA35: 8 | AB35: 0 | AC35: 0 | AE35: 0 | AF35: 0 | AG35: 0 | AH35: 0 | AI35: 0 | AJ35: 1 | AK35: 8 | AL35: 0 | AM35: 22.08 | AN35: 1.5 | AO35: 176.64 | AP35: 0 | AQ35: 176.64 | AR35: 0 | AS35: 0 | AT35: 0 | AU35: 0 | AW35: 0 | AX35: 0 | AZ35: 1 | BA35: 1 | BB35: Medium | BC35: Recurring absences | BD35: On Time | BE35: Not Absent | BF35: No Overtime | BG35: Monitor
A36: AR000035 | B36: EMP0041 | C36: Taylor Vargas | D36: Customer Support | E36: Escalations | F36: MGR004 | G36: Daniel Brooks | H36: South Plant | I36: Customer Care Analyst | J36: Full-Time | K36: 2023-12-21 | L36: 1 to 3 years | M36: 2025-10-01 | N36: 2025-09-29 | O36: 2025-10-01 | P36: Wednesday | Q36: 0 | R36: 0 | S36: Evening | T36: 16:00 | U36: 00:00 | V36: 8 | W36: Fixed | X36: Late Arrival | Y36: 2025-10-01 16:24 | Z36: 2025-10-02 00:00 | AA36: 7.6 | AB36: 24 | AC36: 0 | AE36: 0 | AF36: 0 | AG36: 0 | AH36: 1 | AI36: 0 | AJ36: 1 | AK36: 7.6 | AL36: 0 | AM36: 26.9 | AN36: 1.5 | AO36: 204.44 | AP36: 0 | AQ36: 204.44 | AR36: 0 | AS36: 0 | AT36: 0 | AU36: 0 | AW36: 0 | AX36: 0 | AZ36: 1 | BA36: 1 | BB36: Medium | BC36: Repeat lateness; Recurring absences | BD36: 16-30 minutes | BE36: Not Absent | BF36: No Overtime | BG36: Coaching recommended
A37: AR000036 | B37: EMP0042 | C37: Emerson Irwin | D37: Fulfillment | E37: Packing | F37: MGR001 | G37: Alicia Gomez | H37: North Plant | I37: Fulfillment Lead | J37: Full-Time | K37: 2020-11-25 | L37: 3+ years | M37: 2025-10-01 | N37: 2025-09-29 | O37: 2025-10-01 | P37: Wednesday | Q37: 0 | R37: 0 | S37: Afternoon | T37: 14:00 | U37: 22:00 | V37: 8 | W37: Fixed | X37: Present | Y37: 2025-10-01 14:00 | Z37: 2025-10-01 22:00 | AA37: 8 | AB37: 0 | AC37: 0 | AE37: 0 | AF37: 0 | AG37: 0 | AH37: 0 | AI37: 0 | AJ37: 1 | AK37: 8 | AL37: 0 | AM37: 29.13 | AN37: 1.5 | AO37: 233.04 | AP37: 0 | AQ37: 233.04 | AR37: 0 | AS37: 0 | AT37: 0 | AU37: 0 | AW37: 0 | AX37: 0 | AZ37: 1 | BA37: 1 | BB37: Medium | BC37: Repeat lateness; Recurring absences | BD37: On Time | BE37: Not Absent | BF37: No Overtime | BG37: Monitor
A38: AR000037 | B38: EMP0043 | C38: Paige Powell | D38: Production | E38: Assembly | F38: MGR007 | G38: Owen Carter | H38: South Plant | I38: Line Lead | J38: Full-Time | K38: 2025-08-16 | L38: Under 90 days | M38: 2025-10-01 | N38: 2025-09-29 | O38: 2025-10-01 | P38: Wednesday | Q38: 0 | R38: 0 | S38: Morning | T38: 06:00 | U38: 14:00 | V38: 8 | W38: Fixed | X38: Present | Y38: 2025-10-01 06:00 | Z38: 2025-10-01 14:00 | AA38: 8 | AB38: 0 | AC38: 0 | AE38: 0 | AF38: 0 | AG38: 0 | AH38: 0 | AI38: 0 | AJ38: 1 | AK38: 8 | AL38: 0 | AM38: 28.38 | AN38: 1.5 | AO38: 227.04 | AP38: 0 | AQ38: 227.04 | AR38: 0 | AS38: 0 | AT38: 0 | AU38: 0 | AW38: 0 | AX38: 0 | AZ38: 1 | BA38: 1 | BB38: Medium | BC38: Repeat lateness; Repeated data quality exceptions | BD38: On Time | BE38: Not Absent | BF38: No Overtime | BG38: Monitor
A39: AR000038 | B39: EMP0044 | C39: Jordan Anderson | D39: Maintenance | E39: Equipment Repair | F39: MGR013 | G39: Miles Bennett | H39: Distribution Center | I39: Maintenance Lead | J39: Full-Time | K39: 2025-07-13 | L39: Under 90 days | M39: 2025-10-01 | N39: 2025-09-29 | O39: 2025-10-01 | P39: Wednesday | Q39: 0 | R39: 0 | S39: Morning | T39: 06:00 | U39: 14:00 | V39: 8 | W39: Fixed | X39: Present | Y39: 2025-10-01 06:00 | Z39: 2025-10-01 14:00 | AA39: 8 | AB39: 0 | AC39: 0 | AE39: 0 | AF39: 0 | AG39: 0 | AH39: 0 | AI39: 0 | AJ39: 1 | AK39: 8 | AL39: 0 | AM39: 29.81 | AN39: 1.5 | AO39: 238.48 | AP39: 0 | AQ39: 238.48 | AR39: 0 | AS39: 0 | AT39: 0 | AU39: 0 | AW39: 0 | AX39: 0 | AZ39: 0 | BA39: 0 | BB39: Low | BC39: Repeated data quality exceptions | BD39: On Time | BE39: Not Absent | BF39: No Overtime | BG39: No action
A40: AR000039 | B40: EMP0045 | C40: Jasmine Coleman | D40: Customer Support | E40: Tier 1 Support | F40: MGR005 | G40: Nina Patel | H40: South Plant | I40: Customer Care Analyst | J40: Part-Time | K40: 2025-07-30 | L40: Under 90 days | M40: 2025-10-01 | N40: 2025-09-29 | O40: 2025-10-01 | P40: Wednesday | Q40: 0 | R40: 0 | S40: Afternoon | T40: 14:00 | U40: 22:00 | V40: 8 | W40: Part-Time | X40: Present | Y40: 2025-10-01 14:00 | Z40: 2025-10-01 22:00 | AA40: 8 | AB40: 0 | AC40: 0 | AE40: 0 | AF40: 0 | AG40: 0 | AH40: 0 | AI40: 0 | AJ40: 1 | AK40: 8 | AL40: 0 | AM40: 28.88 | AN40: 1.5 | AO40: 231.04 | AP40: 0 | AQ40: 231.04 | AR40: 0 | AS40: 0 | AT40: 0 | AU40: 0 | AW40: 0 | AX40: 0 | AZ40: 1 | BA40: 1 | BB40: Medium | BC40: Repeat lateness; Recurring absences; Repeated data quality exceptions | BD40: On Time | BE40: Not Absent | BF40: No Overtime | BG40: Monitor
A41: AR000040 | B41: EMP0046 | C41: Alex Garcia | D41: Customer Support | E41: Escalations | F41: MGR006 | G41: Harper Lee | H41: South Plant | I41: Support Team Lead | J41: Full-Time | K41: 2021-11-30 | L41: 3+ years | M41: 2025-10-01 | N41: 2025-09-29 | O41: 2025-10-01 | P41: Wednesday | Q41: 0 | R41: 0 | S41: Overnight | T41: 22:00 | U41: 06:00 | V41: 8 | W41: Fixed | X41: Partial Shift | Y41: 2025-10-01 22:00 | Z41: 2025-10-02 06:04 | AA41: 8.07 | AB41: 0 | AC41: 56 | AE41: 0 | AF41: 0 | AG41: 1 | AH41: 0 | AI41: 0 | AJ41: 1 | AK41: 8 | AL41: 1 | AM41: 33.3 | AN41: 1.5 | AO41: 266.4 | AP41: 49.95 | AQ41: 316.35 | AR41: 1 | AS41: 0 | AT41: 1 | AU41: 1 | AV41: EMP0009 | AW41: 0 | AX41: 0 | AZ41: 1 | BA41: 1 | BB41: Medium | BC41: Repeat lateness; High overtime concentration | BD41: On Time | BE41: Not Absent | BF41: 0.5-2.0 hours | BG41: Schedule review
A42: AR000041 | B42: EMP0047 | C42: Avery Lewis | D42: Production | E42: Line A | F42: MGR008 | G42: Maya Johnson | H42: North Plant | I42: Assembly Technician | J42: Part-Time | K42: 2025-09-04 | L42: Under 90 days | M42: 2025-10-01 | N42: 2025-09-29 | O42: 2025-10-01 | P42: Wednesday | Q42: 0 | R42: 0 | S42: Afternoon | T42: 14:00 | U42: 22:00 | V42: 8 | W42: Part-Time | X42: Present | Y42: 2025-10-01 14:00 | Z42: 2025-10-01 22:00 | AA42: 8 | AB42: 0 | AC42: 0 | AE42: 0 | AF42: 0 | AG42: 0 | AH42: 0 | AI42: 0 | AJ42: 1 | AK42: 8 | AL42: 0 | AM42: 23.66 | AN42: 1.5 | AO42: 189.28 | AP42: 0 | AQ42: 189.28 | AR42: 0 | AS42: 0 | AT42: 0 | AU42: 0 | AW42: 0 | AX42: 0 | AZ42: 1 | BA42: 1 | BB42: Medium | BC42: Repeat lateness | BD42: On Time | BE42: Not Absent | BF42: No Overtime | BG42: Monitor
A43: AR000042 | B43: EMP0048 | C43: Oscar Vargas | D43: Maintenance | E43: Preventive Maintenance | F43: MGR012 | G43: Sofia Rivera | H43: Distribution Center | I43: Maintenance Lead | J43: Full-Time | K43: 2025-04-09 | L43: 90 days to 1 year | M43: 2025-10-01 | N43: 2025-09-29 | O43: 2025-10-01 | P43: Wednesday | Q43: 0 | R43: 0 | S43: Evening | T43: 16:00 | U43: 00:00 | V43: 8 | W43: Fixed | X43: Present | Y43: 2025-10-01 16:00 | Z43: 2025-10-02 00:00 | AA43: 8 | AB43: 0 | AC43: 0 | AE43: 0 | AF43: 0 | AG43: 0 | AH43: 0 | AI43: 0 | AJ43: 1 | AK43: 8 | AL43: 0 | AM43: 28.48 | AN43: 1.5 | AO43: 227.84 | AP43: 0 | AQ43: 227.84 | AR43: 0 | AS43: 0 | AT43: 0 | AU43: 0 | AW43: 0 | AX43: 0 | AZ43: 1 | BA43: 1 | BB43: Medium | BC43: Recurring absences | BD43: On Time | BE43: Not Absent | BF43: No Overtime | BG43: Monitor
...
